<?xml version="1.0"?>
<robot name="SimpleRobotArm">
    <link name="base">
        <visual >
            <origin rpy="0.0 0.0 0.0" xyz="0.0 -0.0 0.0" />
            <geometry >
                <box size="0.2 0.2 0.1" />
            </geometry>
        </visual>
        <visual >
            <origin rpy="0.0 0.0 0.0" xyz="0.0 -0.0 0.1" />
            <geometry >
                <sphere radius="0.025" />
            </geometry>
        </visual>
        <visual >
            <origin rpy="0.0 0.0 0.0" xyz="0.0 -0.0 0.4" />
            <geometry >
                <sphere radius="0.0249999985" />
            </geometry>
        </visual>
        <visual >
            <origin rpy="0.0 0.0 0.0" xyz="0.0 -0.0 0.700000048" />
            <geometry >
                <sphere radius="0.0249999985" />
            </geometry>
        </visual>
    </link>
    <joint name="joint.hinge_from_base" type="continuous">
        <parent link="base" />
        <child link="shoulder" />
        <origin rpy="-0.0 0.0 -0.0" xyz="0.0 -0.0 0.100000024" />
        <axis xyz="0.0 -1.0 0.0" />
        <limit velocity="100.0" effort="0.0" />
    </joint>
    <link name="shoulder">
        <visual >
            <origin rpy="0.0 0.0 0.0" xyz="0.0 -0.0 0.0" />
            <geometry >
                <cylinder radius="0.035" length="0.2" />
            </geometry>
        </visual>
    </link>
    <joint name="joint.hinge_from_shoulder" type="continuous">
        <parent link="shoulder" />
        <child link="elbow" />
        <origin rpy="-0.0 0.0 -0.0" xyz="0.0 -0.0 0.300000012" />
        <axis xyz="0.0 -1.0 0.0" />
        <limit velocity="100.0" effort="0.0" />
    </joint>
    <link name="elbow">
        <visual >
            <origin rpy="0.0 0.0 0.0" xyz="0.0 -0.0 0.0" />
            <geometry >
                <cylinder radius="0.035" length="0.2" />
            </geometry>
        </visual>
    </link>
    <joint name="joint.hinge_from_elbow" type="continuous">
        <parent link="elbow" />
        <child link="hand" />
        <origin rpy="-0.0 0.0 -0.0" xyz="0.0 -0.0 0.29999996399999995" />
        <axis xyz="0.0 -1.0 0.0" />
        <limit velocity="100.0" effort="0.0" />
    </joint>
    <link name="hand">
        <visual >
            <origin rpy="0.0 0.0 0.0" xyz="0.0 -0.0 0.0" />
            <geometry >
                <box size="0.05 0.05 0.1" />
            </geometry>
        </visual>
    </link>
</robot>
