<?xml version="1.0"?>
<robot name="ur10">
    <link name="world"/>

    <link name="base_link">
        <visual >
            <origin rpy="0.0 0.0 0.0" xyz="0.0 -0.0 0.0" />
            <geometry >
                <box size="0.08355 0.075 0.019" />
            </geometry>
        </visual>
    </link>
    <joint name="world_to_baselink" type="fixed">
        <parent link="world" />
        <child link="base_link" />
        <origin rpy="0.0 0.0 -0.0" xyz="0.0 0.0 0.0" />

    </joint>
    <joint name="shoulder_pan_joint" type="continuous">
        <parent link="base_link" />
        <child link="shoulder_link" />
        <origin rpy="-0.0 0.0 -0.0" xyz="0.0 -0.0 0.0364999771" />
        <axis xyz="0.0 -0.0 1.0" />
        <limit velocity="500.0" effort="10.0" />
    </joint>
    <link name="shoulder_link">
        <visual >
            <origin rpy="0 0 0" xyz="0.00138993561 1.80751085e-05 0.005407788" />
            <geometry >
                <box size="0.08861007 0.07516342 0.0805922151" />
            </geometry>
        </visual>
    </link>
    <joint name="shoulder_lift_joint" type="continuous">
        <parent link="shoulder_link" />
        <child link="upper_arm_link" />
        <origin rpy="-0.0 0.0 -0.0" xyz="-0.0855 -0.0 0.0915000439" />
        <axis xyz="-1.0 -0.0 0.0" />
        <limit velocity="500.0" effort="10.0" />
    </joint>
    <link name="upper_arm_link">
        <visual >
            <origin rpy="0 0 0" xyz="0.00138993561 1.80751085e-05 0.005407788" />
            <geometry >
                <box size="0.08861007 0.07516342 0.0805922151" />
            </geometry>
        </visual>
        <visual >
            <origin rpy="0 0 0" xyz="0.0628492758 0.0100024287 0.0745239258" />
            <geometry >
                <box size="0.06345073 0.0599891022 0.06847392" />
            </geometry>
        </visual>
        <visual >
            <origin rpy="0 0 0" xyz="0.0 -0.0 0.23709999" />
            <geometry >
                <box size="0.075 0.075 0.2303" />
            </geometry>
        </visual>
    </link>
    <joint name="elbow_joint" type="continuous">
        <parent link="upper_arm_link" />
        <child link="forearm_link" />
        <origin rpy="-0.0 0.0 -0.0" xyz="-0.022499999999999992 -0.0 0.619999979" />
        <axis xyz="1.0 -0.0 0.0" />
        <limit velocity="500.0" effort="10.0" />
    </joint>
    <link name="forearm_link">
        <visual >
            <origin rpy="0 0 0" xyz="0.004050866 0.000140544027 0.06518407" />
            <geometry >
                <box size="0.0499491356 0.0454888642 0.05938407" />
            </geometry>
        </visual>
        <visual >
            <origin rpy="0 0 0" xyz="-0.00427554 -0.0207261965 0.0222361814" />
            <geometry >
                <box size="0.058 0.225649983 0.058" />
            </geometry>
        </visual>
        <visual >
            <origin rpy="0 0 0" xyz="-0.013897771 -0.00151552632 0.01525671" />
            <geometry >
                <box size="0.0600000024 0.06388664 0.063175" />
            </geometry>
        </visual>
    </link>
    <joint name="wrist_1_joint" type="continuous">
        <parent link="forearm_link" />
        <child link="wrist_1_link" />
        <origin rpy="-0.0 0.0 -0.0" xyz="-0.0038402560000000002 0.0100000147 0.5644004600000001" />
        <axis xyz="-2.0 -0.0 0.0" />
        <limit velocity="500.0" effort="10.0" />
    </joint>
    <link name="wrist_1_link">
        <visual >
            <origin rpy="0 0 0" xyz="0.004050866 0.000140544027 0.06518407" />
            <geometry >
                <box size="0.0499491356 0.0454888642 0.05938407" />
            </geometry>
        </visual>
    </link>
    <joint name="wrist_2_joint" type="continuous">
        <parent link="wrist_1_link" />
        <child link="wrist_2_link" />
        <origin rpy="-0.0 0.0 -0.0" xyz="-0.05385033 -0.010000012837354851 0.06189990000000001" />
        <axis xyz="0.0 -0.0 1.0" />
        <limit velocity="500.0" effort="10.0" />
    </joint>
    <link name="wrist_2_link">
        <visual >
            <origin rpy="0 0 0" xyz="0.004050866 0.000140544027 0.06518407" />
            <geometry >
                <box size="0.0499491356 0.0454888642 0.05938407" />
            </geometry>
        </visual>
    </link>
    <joint name="wrist_3_joint" type="continuous">
        <parent link="wrist_2_link" />
        <child link="wrist_3_link" />
        <origin rpy="1.471582213606204e-15 1.5707963267948963 1.4715822136062052e-15" xyz="-0.06019978200000001 -0.0 0.05550002999999992" />
        <axis xyz="0.0 -1.4715822136062044e-15 1.0000000000000002" />
        <limit velocity="500.0" effort="10.0" />
    </joint>
    <link name="wrist_3_link" />
    <joint name="ee_fixed_joint" type="fixed">
        <parent link="wrist_3_link" />
        <child link="ee_link" />
        <origin rpy="3.5527128400000008e-15 0.0 -0.0" xyz="-0.005500231999999994 4.65661285e-09 -0.001800299999999977" />
    </joint>
    <link name="ee_link">
        <visual >
            <origin rpy="0 0 0" xyz="0.0264006 -0.06721881 0.01342369" />
            <geometry >
                <box size="0.04505 0.04499998 0.01525" />
            </geometry>
        </visual>
    </link>
</robot>
