<?xml version="1.0"?>
<robot  name="ZOSimSimpleBot" >
 <link  name="base_link" />
 <joint  type="revolute"  name="right_wheel_motor" >
  <parent  link="base_link" />
  <child  link="right_wheel" />
  <origin  xyz="0.066 -0.156 -0.014"  rpy="-1.5707963267948963 0.0 -0.0" />
  <axis  xyz="0.0 -0.0 1.0000000000000002" />
 </joint>
 <joint  type="revolute"  name="left_wheel_motor" >
  <parent  link="base_link" />
  <child  link="left_wheel" />
  <origin  xyz="0.066 0.156 -0.014"  rpy="-1.5707963267948963 0.0 -0.0" />
  <axis  xyz="0.0 -0.0 1.0000000000000002" />
 </joint>
 <link  name="lidar_2d" />
 <joint  type="fixed"  name="base_link_to_lidar_2d" >
  <origin  xyz="0.0 -0.0 0.1652"  rpy="-0.0 0.0 -0.0" />
  <parent  link="base_link" />
  <child  link="lidar_2d" />
 </joint>
 <link  name="rgb_camera" />
 <joint  type="fixed"  name="base_link_to_rgb_camera" >
  <origin  xyz="0.0 -0.0 0.182199985"  rpy="3.1415925661670134 0.0 -0.0" />
  <parent  link="base_link" />
  <child  link="rgb_camera" />
 </joint>
 <link  name="Cube" >
  <visual >
   <geometry >
    <box  size="0.01 0.009999999999999997 0.009999999999999997" />
   </geometry>
  </visual>
 </link>
 <joint  type="fixed"  name="rgb_camera_to_Cube" >
  <origin  xyz="0.0 -0.0 0.0285"  rpy="-0.0 0.0 -0.0" />
  <parent  link="rgb_camera" />
  <child  link="Cube" />
 </joint>
 <link  name="main_chassis_body" >
  <visual >
   <geometry >
    <box  size="0.3 0.287 0.08" />
   </geometry>
  </visual>
 </link>
 <joint  type="fixed"  name="base_link_to_main_chassis_body" >
  <origin  xyz="0.0 -0.0 0.0"  rpy="-0.0 0.0 -0.0" />
  <parent  link="base_link" />
  <child  link="main_chassis_body" />
 </joint>
 <link  name="right_castor" >
  <visual >
   <geometry >
    <sphere  radius="0.005" />
   </geometry>
  </visual>
 </link>
 <joint  type="fixed"  name="base_link_to_right_castor" >
  <origin  xyz="-0.1379 -0.1094 -0.042"  rpy="-0.0 0.0 -0.0" />
  <parent  link="base_link" />
  <child  link="right_castor" />
 </joint>
 <link  name="left_castor" >
  <visual >
   <geometry >
    <sphere  radius="0.005" />
   </geometry>
  </visual>
 </link>
 <joint  type="fixed"  name="base_link_to_left_castor" >
  <origin  xyz="-0.1379 0.1094 -0.042"  rpy="-0.0 0.0 -0.0" />
  <parent  link="base_link" />
  <child  link="left_castor" />
 </joint>
 <link  name="right_wheel" >
  <visual >
   <geometry >
    <cylinder  length="0.019999999999999997"  radius="0.032999999999999995" />
   </geometry>
  </visual>
 </link>
 <link  name="left_wheel" >
  <visual >
   <geometry >
    <cylinder  length="0.019999999999999997"  radius="0.032999999999999995" />
   </geometry>
  </visual>
 </link>
</robot>
